Workbook
Name _YouTubeDashboardBuildStatus: "OK"
Name sliMonth: #N/A
Name sliYear: #N/A

Sheet Index
F5: I n d e x
F7: Pages | G7: Description
F8: V1 | G8: RawData
F9: V2 | G9: Highest Revenue & Engagement Analysis for specific region Analysis
F10: V3 | G10: Cleaned
F11: V4 | G11: Pivots Tables
F12: V5 | G12: Pivots Charts

Sheet V1
A1: Date | B1: Month | C1: Views | D1: Average View duration | E1: Subscribers Gained | F1: Watch Time Hours | G1: Revenue $ | H1: Age Group | I1: Gender | J1: Device | K1: Source | L1: Country
A2: 2025-01-01 | B2: Jan | C2: 615 | D2: 10 | E2: 38 | F2: 212 | G2: 1580.92 | H2: 45-54 | I2: Male | J2: Mobile | K2: YouTube Search | L2: United States
A3: 2025-01-02 | B3: Jan | C3: 4667 | D3: 21 | E3: 0 | F3: 349 | G3: 749.5 | H3: 35-44 | I3: Female | J3: Mobile | K3: Browse Features | L3: United States
A4: 2025-01-03 | B4: Jan | C4: 2218 | D4: 41 | E4: -1 | F4: 210 | G4: 736.53 | H4: 18-24 | I4: Female | J4: Desktop | K4: Browse Features | L4: United States
A5: 2025-01-04 | B5: Jan | C5: 1077 | D5: 15 | E5: 41 | F5: 40 | G5: 2059.24 | H5: 18-24 | I5: Male | J5: Tablet | K5: Suggested Videos | L5: United States
A6: 2025-01-05 | B6: Jan | C6: 868 | D6: 10 | E6: 49 | F6: 175 | G6: 256.43 | H6: 25-34 | I6: Male | J6: Mobile | K6: YouTube Search | L6: United States
A7: 2025-01-06 | B7: Jan | C7: 1974 | D7: 31 | E7: 3 | F7: 161 | G7: 117 | H7: 25-34 | I7: Male | J7: Mobile | K7: Direct | L7: United States
A8: 2025-01-07 | B8: Jan | C8: 702 | D8: 22 | E8: 9 | F8: 288 | G8: 694.7 | H8: 35-44 | I8: Female | J8: Mobile | K8: YouTube Search | L8: United States
A9: 2025-01-08 | B9: Jan | C9: 3117 | D9: 27 | E9: 2 | F9: 142 | G9: 1330.48 | H9: 18-24 | I9: Male | J9: Mobile | K9: YouTube Search | L9: United States
A10: 2025-01-09 | B10: Jan | C10: 1448 | D10: 17 | E10: 28 | F10: 212 | G10: 1040.24 | H10: 55+ | I10: Male | J10: Mobile | K10: External | L10: United States
A11: 2025-01-10 | B11: Jan | C11: 707 | D11: 18 | E11: 39 | F11: 28 | G11: 1474.64 | H11: 45-54 | I11: Female | J11: Mobile | K11: YouTube Search | L11: United States
A12: 2025-01-11 | B12: Jan | C12: 3027 | D12: 22 | E12: -5 | F12: 146 | G12: 1529.31 | H12: 13-17 | I12: Male | J12: Mobile | K12: External | L12: United States
A13: 2025-01-12 | B13: Jan | C13: 4138 | D13: 3 | E13: 30 | F13: 97 | G13: 2309.11 | H13: 35-44 | I13: Male | J13: Mobile | K13: Browse Features | L13: United States
... A131: 2025-05-10 | B131: May | C131: 3944 | D131: 37 | E131: 28 | F131: 386 | G131: 318.9 | H131: 35-44 | I131: Male | J131: Mobile | K131: Direct | L131: India
A132: 45788 | B132: May | C132: 3279 | D132: 31 | E132: 47 | F132: 447 | G132: 1567.17 | H132: 35-44 | I132: Male | J132: TV | K132: Suggested Videos | L132: India
A133: 2025-05-12 | B133: May | C133: 3724 | D133: 39 | E133: 24 | F133: 67 | G133: 1914.89 | H133: 35-44 | I133: Male | J133: TV | K133: External | L133: India
A134: 2025-05-13 | B134: May | C134: 4606 | D134: 21 | E134: 42 | F134: 386 | G134: 2492.41 | H134: 25-34 | I134: Male | J134: Tablet | K134: Direct | L134: India
A135: 2025-05-14 | B135: May | C135: 2996 | D135: 11 | E135: 20 | F135: 304 | G135: 463.51 | H135: 35-44 | I135: Male | J135: Desktop | K135: Suggested Videos | L135: India
A136: 2025-05-15 | B136: May | C136: 4581 | D136: 28 | E136: 35 | F136: 374 | G136: 942.86 | H136: 18-24 | I136: Male | J136: Mobile | K136: Suggested Videos | L136: India
A137: 2025-05-16 | B137: May | C137: 4560 | D137: 14 | E137: 44 | F137: 60 | G137: 2274.64 | H137: 35-44 | I137: Male | J137: Mobile | K137: Direct | L137: India
A138: 2025-05-17 | B138: May | C138: 4845 | D138: 18 | E138: 27 | F138: 394 | G138: 1194.12 | H138: 25-34 | I138: Male | J138: Desktop | K138: Suggested Videos | L138: India
A139: 2025-05-18 | B139: May | C139: 3953 | D139: 9 | E139: 9 | F139: 174 | G139: 1627.89 | H139: 35-44 | I139: Male | J139: Mobile | K139: Browse Features | L139: India
A140: 2025-05-19 | B140: May | C140: 3275 | D140: 43 | E140: 24 | F140: 418 | G140: 1362.01 | H140: 35-44 | I140: Male | J140: Tablet | K140: Browse Features | L140: India
A141: 2025-05-20 | B141: May | C141: 4208 | D141: 45 | E141: 3 | F141: 322 | G141: 1641.01 | H141: 45-54 | I141: Male | J141: Mobile | K141: Suggested Videos | L141: India
A142: 2025-05-21 | B142: May | C142: 626 | D142: 17 | E142: 30 | F142: 128 | G142: 1675.25 | H142: 25-34 | I142: Male | J142: Desktop | K142: Channel Pages | L142: India
A143: 2025-05-22 | B143: May | C143: 3188 | D143: 24 | E143: -1 | F143: 36 | G143: 956.18 | H143: 55+ | I143: Male | J143: Mobile | K143: Direct | L143: India
A144: 2025-05-23 | B144: May | C144: 1925 | D144: 15 | E144: 27 | F144: 360 | G144: 1816.33 | H144: 25-34 | I144: Male | J144: Desktop | K144: External | L144: India
... A366: 2025-12-31 | B366: Dec | C366: 2851 | D366: 10 | E366: 42 | F366: 352 | G366: 1623.67 | H366: 25-34 | I366: Female | J366: Mobile | K366: Channel Pages | L366: Germany
A367: 46023 | B367: Jan | C367: 3515 | D367: 43 | E367: 14 | F367: 377 | G367: 757.57 | H367: 25-34 | I367: Female | J367: Desktop | K367: Channel Pages | L367: Germany
A368: 46024 | B368: Jan | C368: 3213 | D368: 20 | E368: 36 | F368: 328 | G368: 1136.2 | H368: 35-44 | I368: Male | J368: Mobile | K368: Browse Features | L368: Germany
A369: 46025 | B369: Jan | C369: 4652 | D369: 26 | E369: 47 | F369: 345 | G369: 2182.93 | H369: 18-24 | I369: Male | J369: Mobile | K369: Browse Features | L369: Germany
A370: 46026 | B370: Jan | C370: 2843 | D370: 16 | E370: 17 | F370: 375 | G370: 247.98 | H370: 25-34 | I370: Female | J370: Mobile | K370: Direct | L370: Germany
A371: 46027 | B371: Jan | C371: 2207 | D371: 31 | E371: 1 | F371: 267 | G371: 567.62 | H371: 18-24 | I371: Female | J371: Desktop | K371: Suggested Videos | L371: Germany
A372: 46028 | B372: Jan | C372: 1999 | D372: 20 | E372: 23 | F372: 48 | G372: 1736.58 | H372: 18-24 | I372: Male | J372: Mobile | K372: YouTube Search | L372: Germany
A373: 46029 | B373: Jan | C373: 2497 | D373: 16 | E373: 31 | F373: 92 | G373: 1791.42 | H373: 18-24 | I373: Male | J373: Desktop | K373: YouTube Search | L373: Germany
A374: 46030 | B374: Jan | C374: 1807 | D374: 14 | E374: -3 | F374: 332 | G374: 300.59 | H374: 55+ | I374: Male | J374: Desktop | K374: Suggested Videos | L374: Germany
A375: 46031 | B375: Jan | C375: 2530 | D375: 24 | E375: 29 | F375: 300 | G375: 907.25 | H375: 13-17 | I375: Male | J375: Mobile | K375: Suggested Videos | L375: Germany
A376: 46032 | B376: Jan | C376: 2724 | D376: 7 | E376: 20 | F376: 224 | G376: 1264.42 | H376: 18-24 | I376: Female | J376: Mobile | K376: Suggested Videos | L376: Germany
A377: 46033 | B377: Jan | C377: 2881 | D377: 31 | E377: 26 | F377: 403 | G377: 284.5 | H377: 25-34 | I377: Male | J377: Tablet | K377: Suggested Videos | L377: Germany
A378: 46034 | B378: Jan | C378: 5018 | D378: 11 | E378: 59 | F378: 428 | G378: 460.3 | H378: 25-34 | I378: Female | J378: Desktop | K378: YouTube Search | L378: Germany
...

Sheet V2
E5: Country | F5: Revenue | G5: Views | H5: Average View Duration | I5: Subscriber Gained | J5: Watch Time Hours
E6: {=_xlfn.UNIQUE('V1'!L2:L578)} -> United States | F6: =SUMIF('V1'!L2:L578,'V2'!E6,'V1'!G2:G578) -> 165615.27 | G6: =SUMIF('V1'!L2:L578,'V2'!E6,'V1'!C2:C578) -> 357689.2 | H6: =SUMIF('V1'!L2:L578,'V2'!E6,'V1'!D2:D578) -> 3420 | I6: =SUMIF('V1'!L2:L578,'V2'!E6,'V1'!E2:E578) -> 2974 | J6: =SUMIF('V1'!L2:L578,'V2'!E6,'V1'!F2:F578) -> 33284
E7: India | F7: =SUMIF('V1'!L3:L579,'V2'!E7,'V1'!G3:G579) -> 106779.27 | G7: =SUMIF('V1'!L3:L579,'V2'!E7,'V1'!C3:C579) -> 247616 | H7: =SUMIF('V1'!L3:L579,'V2'!E7,'V1'!D3:D579) -> 1995 | I7: =SUMIF('V1'!L3:L579,'V2'!E7,'V1'!E3:E579) -> 1905 | J7: =SUMIF('V1'!L3:L579,'V2'!E7,'V1'!F3:F579) -> 19499
E8: Canada | F8: =SUMIF('V1'!L4:L580,'V2'!E8,'V1'!G4:G580) -> 62127.83 | G8: =SUMIF('V1'!L4:L580,'V2'!E8,'V1'!C4:C580) -> 116032 | H8: =SUMIF('V1'!L4:L580,'V2'!E8,'V1'!D4:D580) -> 1011 | I8: =SUMIF('V1'!L4:L580,'V2'!E8,'V1'!E4:E580) -> 1185 | J8: =SUMIF('V1'!L4:L580,'V2'!E8,'V1'!F4:F580) -> 10139
E9: United Kingdom | F9: =SUMIF('V1'!L5:L581,'V2'!E9,'V1'!G5:G581) -> 48082.81 | G9: =SUMIF('V1'!L5:L581,'V2'!E9,'V1'!C5:C581) -> 104711 | H9: =SUMIF('V1'!L5:L581,'V2'!E9,'V1'!D5:D581) -> 962 | I9: =SUMIF('V1'!L5:L581,'V2'!E9,'V1'!E5:E581) -> 724 | J9: =SUMIF('V1'!L5:L581,'V2'!E9,'V1'!F5:F581) -> 8786
E10: Australia | F10: =SUMIF('V1'!L6:L582,'V2'!E10,'V1'!G6:G582) -> 41971.21 | G10: =SUMIF('V1'!L6:L582,'V2'!E10,'V1'!C6:C582) -> 99114 | H10: =SUMIF('V1'!L6:L582,'V2'!E10,'V1'!D6:D582) -> 914 | I10: =SUMIF('V1'!L6:L582,'V2'!E10,'V1'!E6:E582) -> 977 | J10: =SUMIF('V1'!L6:L582,'V2'!E10,'V1'!F6:F582) -> 7381
E11: Japan | F11: =SUMIF('V1'!L7:L583,'V2'!E11,'V1'!G7:G583) -> 36951.39 | G11: =SUMIF('V1'!L7:L583,'V2'!E11,'V1'!C7:C583) -> 92816 | H11: =SUMIF('V1'!L7:L583,'V2'!E11,'V1'!D7:D583) -> 746 | I11: =SUMIF('V1'!L7:L583,'V2'!E11,'V1'!E7:E583) -> 710 | J11: =SUMIF('V1'!L7:L583,'V2'!E11,'V1'!F7:F583) -> 8050
E12: Germany | F12: =SUMIF('V1'!L8:L584,'V2'!E12,'V1'!G8:G584) -> 51470.58 | G12: =SUMIF('V1'!L8:L584,'V2'!E12,'V1'!C8:C584) -> 112767.2 | H12: =SUMIF('V1'!L8:L584,'V2'!E12,'V1'!D8:D584) -> 936 | I12: =SUMIF('V1'!L8:L584,'V2'!E12,'V1'!E8:E584) -> 1165 | J12: =SUMIF('V1'!L8:L584,'V2'!E12,'V1'!F8:F584) -> 10061
E13: Brazil | F13: =SUMIF('V1'!L9:L585,'V2'!E13,'V1'!G9:G585) -> 29267 | G13: =SUMIF('V1'!L9:L585,'V2'!E13,'V1'!C9:C585) -> 72483 | H13: =SUMIF('V1'!L9:L585,'V2'!E13,'V1'!D9:D585) -> 455 | I13: =SUMIF('V1'!L9:L585,'V2'!E13,'V1'!E9:E585) -> 668 | J13: =SUMIF('V1'!L9:L585,'V2'!E13,'V1'!F9:F585) -> 5786
E14: France | F14: =SUMIF('V1'!L10:L586,'V2'!E14,'V1'!G10:G586) -> 40606.74 | G14: =SUMIF('V1'!L10:L586,'V2'!E14,'V1'!C10:C586) -> 108389.2 | H14: =SUMIF('V1'!L10:L586,'V2'!E14,'V1'!D10:D586) -> 769 | I14: =SUMIF('V1'!L10:L586,'V2'!E14,'V1'!E10:E586) -> 1070 | J14: =SUMIF('V1'!L10:L586,'V2'!E14,'V1'!F10:F586) -> 8222
E15: Italy | F15: =SUMIF('V1'!L11:L587,'V2'!E15,'V1'!G11:G587) -> 41533.92 | G15: =SUMIF('V1'!L11:L587,'V2'!E15,'V1'!C11:C587) -> 94886.04 | H15: =SUMIF('V1'!L11:L587,'V2'!E15,'V1'!D11:D587) -> 744 | I15: =SUMIF('V1'!L11:L587,'V2'!E15,'V1'!E11:E587) -> 873 | J15: =SUMIF('V1'!L11:L587,'V2'!E15,'V1'!F11:F587) -> 6456
E16: Mexico | F16: =SUMIF('V1'!L12:L588,'V2'!E16,'V1'!G12:G588) -> 23501.94 | G16: =SUMIF('V1'!L12:L588,'V2'!E16,'V1'!C12:C588) -> 54179 | H16: =SUMIF('V1'!L12:L588,'V2'!E16,'V1'!D12:D588) -> 442 | I16: =SUMIF('V1'!L12:L588,'V2'!E16,'V1'!E12:E588) -> 486 | J16: =SUMIF('V1'!L12:L588,'V2'!E16,'V1'!F12:F588) -> 4616
E17: Singapore | F17: =SUMIF('V1'!L13:L589,'V2'!E17,'V1'!G13:G589) -> 18852.51 | G17: =SUMIF('V1'!L13:L589,'V2'!E17,'V1'!C13:C589) -> 46714 | H17: =SUMIF('V1'!L13:L589,'V2'!E17,'V1'!D13:D589) -> 364 | I17: =SUMIF('V1'!L13:L589,'V2'!E17,'V1'!E13:E589) -> 573 | J17: =SUMIF('V1'!L13:L589,'V2'!E17,'V1'!F13:F589) -> 3870
E18: South Africa | F18: =SUMIF('V1'!L14:L590,'V2'!E18,'V1'!G14:G590) -> 18780.38 | G18: =SUMIF('V1'!L14:L590,'V2'!E18,'V1'!C14:C590) -> 47585 | H18: =SUMIF('V1'!L14:L590,'V2'!E18,'V1'!D14:D590) -> 360 | I18: =SUMIF('V1'!L14:L590,'V2'!E18,'V1'!E14:E590) -> 368 | J18: =SUMIF('V1'!L14:L590,'V2'!E18,'V1'!F14:F590) -> 3444
... E20: Spain | F20: =SUMIF('V1'!L16:L592,'V2'!E20,'V1'!G16:G592) -> 12307 | G20: =SUMIF('V1'!L16:L592,'V2'!E20,'V1'!C16:C592) -> 31429.4 | H20: =SUMIF('V1'!L16:L592,'V2'!E20,'V1'!D16:D592) -> 304 | I20: =SUMIF('V1'!L16:L592,'V2'!E20,'V1'!E16:E592) -> 246 | J20: =SUMIF('V1'!L16:L592,'V2'!E20,'V1'!F16:F592) -> 3081

Sheet V3
A1: Date | B1: Month | C1: Views | D1: Average View duration | E1: Subscribers Gained | F1: Watch Time Hours | G1: Revenue $ | H1: Age Group | I1: Gender | J1: Device | K1: Source | L1: Country
A2: 2025-01-01 | B2: Jan | C2: 615 | D2: 10 | E2: 38 | F2: 212 | G2: 1580.92 | H2: 45-54 | I2: Male | J2: Mobile | K2: YouTube Search | L2: United States
A3: 2025-01-02 | B3: Jan | C3: 4667 | D3: 21 | E3: 0 | F3: 349 | G3: 749.5 | H3: 35-44 | I3: Female | J3: Mobile | K3: Browse Features | L3: United States
A4: 2025-01-03 | B4: Jan | C4: 2218 | D4: 41 | E4: -1 | F4: 210 | G4: 736.53 | H4: 18-24 | I4: Female | J4: Desktop | K4: Browse Features | L4: United States
A5: 2025-01-04 | B5: Jan | C5: 1077 | D5: 15 | E5: 41 | F5: 40 | G5: 2059.24 | H5: 18-24 | I5: Male | J5: Tablet | K5: Suggested Videos | L5: United States
A6: 2025-01-05 | B6: Jan | C6: 868 | D6: 10 | E6: 49 | F6: 175 | G6: 256.43 | H6: 25-34 | I6: Male | J6: Mobile | K6: YouTube Search | L6: United States
A7: 2025-01-06 | B7: Jan | C7: 1974 | D7: 31 | E7: 3 | F7: 161 | G7: 117 | H7: 25-34 | I7: Male | J7: Mobile | K7: Direct | L7: United States
A8: 2025-01-07 | B8: Jan | C8: 702 | D8: 22 | E8: 9 | F8: 288 | G8: 694.7 | H8: 35-44 | I8: Female | J8: Mobile | K8: YouTube Search | L8: United States
A9: 2025-01-08 | B9: Jan | C9: 3117 | D9: 27 | E9: 2 | F9: 142 | G9: 1330.48 | H9: 18-24 | I9: Male | J9: Mobile | K9: YouTube Search | L9: United States
A10: 2025-01-09 | B10: Jan | C10: 1448 | D10: 17 | E10: 28 | F10: 212 | G10: 1040.24 | H10: 55+ | I10: Male | J10: Mobile | K10: External | L10: United States
A11: 2025-01-10 | B11: Jan | C11: 707 | D11: 18 | E11: 39 | F11: 28 | G11: 1474.64 | H11: 45-54 | I11: Female | J11: Mobile | K11: YouTube Search | L11: United States
A12: 2025-01-11 | B12: Jan | C12: 3027 | D12: 22 | E12: -5 | F12: 146 | G12: 1529.31 | H12: 13-17 | I12: Male | J12: Mobile | K12: External | L12: United States
A13: 2025-01-12 | B13: Jan | C13: 4138 | D13: 3 | E13: 30 | F13: 97 | G13: 2309.11 | H13: 35-44 | I13: Male | J13: Mobile | K13: Browse Features | L13: United States
... A131: 2025-05-10 | B131: May | C131: 3944 | D131: 37 | E131: 28 | F131: 386 | G131: 318.9 | H131: 35-44 | I131: Male | J131: Mobile | K131: Direct | L131: India
A132: 45788 | B132: May | C132: 3279 | D132: 31 | E132: 47 | F132: 447 | G132: 1567.17 | H132: 35-44 | I132: Male | J132: TV | K132: Suggested Videos | L132: India
A133: 2025-05-12 | B133: May | C133: 3724 | D133: 39 | E133: 24 | F133: 67 | G133: 1914.89 | H133: 35-44 | I133: Male | J133: TV | K133: External | L133: India
A134: 2025-05-13 | B134: May | C134: 4606 | D134: 21 | E134: 42 | F134: 386 | G134: 2492.41 | H134: 25-34 | I134: Male | J134: Tablet | K134: Direct | L134: India
A135: 2025-05-14 | B135: May | C135: 2996 | D135: 11 | E135: 20 | F135: 304 | G135: 463.51 | H135: 35-44 | I135: Male | J135: Desktop | K135: Suggested Videos | L135: India
A136: 2025-05-15 | B136: May | C136: 4581 | D136: 28 | E136: 35 | F136: 374 | G136: 942.86 | H136: 18-24 | I136: Male | J136: Mobile | K136: Suggested Videos | L136: India
A137: 2025-05-16 | B137: May | C137: 4560 | D137: 14 | E137: 44 | F137: 60 | G137: 2274.64 | H137: 35-44 | I137: Male | J137: Mobile | K137: Direct | L137: India
A138: 2025-05-17 | B138: May | C138: 4845 | D138: 18 | E138: 27 | F138: 394 | G138: 1194.12 | H138: 25-34 | I138: Male | J138: Desktop | K138: Suggested Videos | L138: India
A139: 2025-05-18 | B139: May | C139: 3953 | D139: 9 | E139: 9 | F139: 174 | G139: 1627.89 | H139: 35-44 | I139: Male | J139: Mobile | K139: Browse Features | L139: India
A140: 2025-05-19 | B140: May | C140: 3275 | D140: 43 | E140: 24 | F140: 418 | G140: 1362.01 | H140: 35-44 | I140: Male | J140: Tablet | K140: Browse Features | L140: India
A141: 2025-05-20 | B141: May | C141: 4208 | D141: 45 | E141: 3 | F141: 322 | G141: 1641.01 | H141: 45-54 | I141: Male | J141: Mobile | K141: Suggested Videos | L141: India
A142: 2025-05-21 | B142: May | C142: 626 | D142: 17 | E142: 30 | F142: 128 | G142: 1675.25 | H142: 25-34 | I142: Male | J142: Desktop | K142: Channel Pages | L142: India
A143: 2025-05-22 | B143: May | C143: 3188 | D143: 24 | E143: -1 | F143: 36 | G143: 956.18 | H143: 55+ | I143: Male | J143: Mobile | K143: Direct | L143: India
A144: 2025-05-23 | B144: May | C144: 1925 | D144: 15 | E144: 27 | F144: 360 | G144: 1816.33 | H144: 25-34 | I144: Male | J144: Desktop | K144: External | L144: India
... A366: 2025-12-31 | B366: Dec | C366: 2851 | D366: 10 | E366: 42 | F366: 352 | G366: 1623.67 | H366: 25-34 | I366: Female | J366: Mobile | K366: Channel Pages | L366: Germany
A367: 46023 | B367: Jan | C367: 3515 | D367: 43 | E367: 14 | F367: 377 | G367: 757.57 | H367: 25-34 | I367: Female | J367: Desktop | K367: Channel Pages | L367: Germany
A368: 46024 | B368: Jan | C368: 3213 | D368: 20 | E368: 36 | F368: 328 | G368: 1136.2 | H368: 35-44 | I368: Male | J368: Mobile | K368: Browse Features | L368: Germany
A369: 46025 | B369: Jan | C369: 4652 | D369: 26 | E369: 47 | F369: 345 | G369: 2182.93 | H369: 18-24 | I369: Male | J369: Mobile | K369: Browse Features | L369: Germany
A370: 46026 | B370: Jan | C370: 2843 | D370: 16 | E370: 17 | F370: 375 | G370: 247.98 | H370: 25-34 | I370: Female | J370: Mobile | K370: Direct | L370: Germany
A371: 46027 | B371: Jan | C371: 2207 | D371: 31 | E371: 1 | F371: 267 | G371: 567.62 | H371: 18-24 | I371: Female | J371: Desktop | K371: Suggested Videos | L371: Germany
A372: 46028 | B372: Jan | C372: 1999 | D372: 20 | E372: 23 | F372: 48 | G372: 1736.58 | H372: 18-24 | I372: Male | J372: Mobile | K372: YouTube Search | L372: Germany
A373: 46029 | B373: Jan | C373: 2497 | D373: 16 | E373: 31 | F373: 92 | G373: 1791.42 | H373: 18-24 | I373: Male | J373: Desktop | K373: YouTube Search | L373: Germany
A374: 46030 | B374: Jan | C374: 1807 | D374: 14 | E374: -3 | F374: 332 | G374: 300.59 | H374: 55+ | I374: Male | J374: Desktop | K374: Suggested Videos | L374: Germany
A375: 46031 | B375: Jan | C375: 2530 | D375: 24 | E375: 29 | F375: 300 | G375: 907.25 | H375: 13-17 | I375: Male | J375: Mobile | K375: Suggested Videos | L375: Germany
A376: 46032 | B376: Jan | C376: 2724 | D376: 7 | E376: 20 | F376: 224 | G376: 1264.42 | H376: 18-24 | I376: Female | J376: Mobile | K376: Suggested Videos | L376: Germany
A377: 46033 | B377: Jan | C377: 2881 | D377: 31 | E377: 26 | F377: 403 | G377: 284.5 | H377: 25-34 | I377: Male | J377: Tablet | K377: Suggested Videos | L377: Germany
A378: 46034 | B378: Jan | C378: 5018 | D378: 11 | E378: 59 | F378: 428 | G378: 460.3 | H378: 25-34 | I378: Female | J378: Desktop | K378: YouTube Search | L378: Germany
...

Sheet Dashboard_Source
A1: Date | B1: Year | C1: Month | D1: Views | E1: Average View duration | F1: Subscribers Gained | G1: Watch Time Hours | H1: Revenue $ | I1: Age Group | J1: Gender | K1: Device | L1: Source | M1: Country
A2: 45658 | B2: 2025 | C2: Jan | D2: 615 | E2: 10 | F2: 38 | G2: 212 | H2: 1580.92 | I2: 0 | J2: Male | K2: Mobile | L2: YouTube Search | M2: United States
A3: 45659 | B3: 2025 | C3: Jan | D3: 4667 | E3: 21 | F3: 0 | G3: 349 | H3: 749.5 | I3: 0 | J3: Female | K3: Mobile | L3: Browse Features | M3: United States
A4: 45660 | B4: 2025 | C4: Jan | D4: 2218 | E4: 41 | F4: -1 | G4: 210 | H4: 736.53 | I4: 0 | J4: Female | K4: Desktop | L4: Browse Features | M4: United States
A5: 45661 | B5: 2025 | C5: Jan | D5: 1077 | E5: 15 | F5: 41 | G5: 40 | H5: 2059.24 | I5: 0 | J5: Male | K5: Tablet | L5: Suggested Videos | M5: United States
A6: 45662 | B6: 2025 | C6: Jan | D6: 868 | E6: 10 | F6: 49 | G6: 175 | H6: 256.43 | I6: 0 | J6: Male | K6: Mobile | L6: YouTube Search | M6: United States
A7: 45663 | B7: 2025 | C7: Jan | D7: 1974 | E7: 31 | F7: 3 | G7: 161 | H7: 117 | I7: 0 | J7: Male | K7: Mobile | L7: Direct | M7: United States
A8: 45664 | B8: 2025 | C8: Jan | D8: 702 | E8: 22 | F8: 9 | G8: 288 | H8: 694.7 | I8: 0 | J8: Female | K8: Mobile | L8: YouTube Search | M8: United States
A9: 45665 | B9: 2025 | C9: Jan | D9: 3117 | E9: 27 | F9: 2 | G9: 142 | H9: 1330.48 | I9: 0 | J9: Male | K9: Mobile | L9: YouTube Search | M9: United States
A10: 45666 | B10: 2025 | C10: Jan | D10: 1448 | E10: 17 | F10: 28 | G10: 212 | H10: 1040.24 | I10: 55 | J10: Male | K10: Mobile | L10: External | M10: United States
A11: 45667 | B11: 2025 | C11: Jan | D11: 707 | E11: 18 | F11: 39 | G11: 28 | H11: 1474.64 | I11: 0 | J11: Female | K11: Mobile | L11: YouTube Search | M11: United States
A12: 45668 | B12: 2025 | C12: Jan | D12: 3027 | E12: 22 | F12: -5 | G12: 146 | H12: 1529.31 | I12: 0 | J12: Male | K12: Mobile | L12: External | M12: United States
A13: 45669 | B13: 2025 | C13: Jan | D13: 4138 | E13: 3 | F13: 30 | G13: 97 | H13: 2309.11 | I13: 0 | J13: Male | K13: Mobile | L13: Browse Features | M13: United States
... A578: 46234 | B578: 2026 | C578: Jul | D578: 1822.5 | E578: 20 | F578: 27 | G578: 74 | H578: 1361 | I578: 0 | J578: Female | K578: Tablet | L578: Browse Features | M578: United States

Sheet V4
A2: Monthly Views Trend | H2: Traffic Source Analysis | K2: Device Type Performance | N2: Subscriber Growth Analysis | Q2: Revenue by Country | T2: Monthly Views Trend
A3: Month | B3: Total Views | C3: Total Subscribers | D3: Total Watch Time Hours | E3: Estimated Revenue | F3: Avg View Duration | H3: Source | I3: Total Views | K3: Device | L3: Total Views | N3: Month | O3: Total Subscribers Gained | Q3: Country | R3: Total Revenue | T3: Total Views | U3: Year
A4: Jan | B4: 164327 | C4: 1531 | D4: 14536 | E4: 72829.07 | F4: 20.935484 | H4: Browse Features | I4: 289264.94 | K4: Desktop | L4: 350488.9 | N4: Jan | O4: 1531 | Q4: United States | R4: 165615.27 | T4: Month | U4: 2025 | V4: 2026
A5: Feb | B5: 160948 | C5: 1328 | D5: 13110 | E5: 62348.21 | F5: 22.142857 | H5: Channel Pages | I5: 135560.6 | K5: Mobile | L5: 953468.8 | N5: Feb | O5: 1328 | Q5: India | R5: 106779.27 | T5: Jan | U5: 76271 | V5: 88056
A6: Mar | B6: 167799 | C6: 1594 | D6: 14988 | E6: 75948.48 | F6: 25.193548 | H6: Direct | I6: 141528.3 | K6: Tablet | L6: 194435.4 | N6: Mar | O6: 1594 | Q6: Canada | R6: 62127.83 | T6: Feb | U6: 76239 | V6: 84709
A7: Apr | B7: 178561 | C7: 1447 | D7: 14873 | E7: 71439.92 | F7: 25.533333 | H7: External | I7: 203122.1 | K7: TV | L7: 132285.94 | N7: Apr | O7: 1447 | Q7: Germany | R7: 51470.58 | T7: Mar | U7: 67395 | V7: 100404
A8: May | B8: 192043 | C8: 1629 | D8: 16279 | E8: 81575.42 | F8: 24.935484 | H8: Suggested Videos | I8: 425255.2 | K8: Grand Total | L8: 1630679 | N8: May | O8: 1629 | Q8: United Kingdom | R8: 48082.81 | T8: Apr | U8: 91399 | V8: 87162
A9: Jun | B9: 180433.64 | C9: 1509 | D9: 13502 | E9: 74498.19 | F9: 22.783333 | H9: YouTube Search | I9: 435947.9 | N9: Jun | O9: 1509 | Q9: Australia | R9: 41971.21 | T9: May | U9: 99963 | V9: 92080
A10: Jul | B10: 165220.4 | C10: 1508 | D10: 14238 | E10: 82908.22 | F10: 25.16129 | H10: Grand Total | I10: 1630679 | N10: Jul | O10: 1508 | Q10: Italy | R10: 41533.92 | T10: Jun | U10: 94232 | V10: 86201.64
A11: Aug | B11: 82157 | C11: 851 | D11: 7316 | E11: 41921.88 | F11: 21.451613 | N11: Aug | O11: 851 | Q11: France | R11: 40606.74 | T11: Jul | U11: 85295 | V11: 79925.4
A12: Sep | B12: 75182 | C12: 555 | D12: 7080 | E12: 36286.51 | F12: 22.366667 | N12: Sep | O12: 555 | Q12: Japan | R12: 36951.39 | T12: Aug | U12: 82157
A13: Oct | B13: 88470 | C13: 783 | D13: 6347 | E13: 36637.35 | F13: 30.419355 | N13: Oct | O13: 783 | Q13: Brazil | R13: 29267 | T13: Sep | U13: 75182
A14: Nov | B14: 78853 | C14: 789 | D14: 7482 | E14: 40744.05 | F14: 22.4 | N14: Nov | O14: 789 | Q14: Mexico | R14: 23501.94 | T14: Oct | U14: 88470
A15: Dec | B15: 96685 | C15: 860 | D15: 7064 | E15: 37382.63 | F15: 23.774194 | N15: Dec | O15: 860 | Q15: Singapore | R15: 18852.51 | T15: Nov | U15: 78853
A16: Grand Total | B16: 1630679 | C16: 14384 | D16: 136815 | E16: 714519.93 | F16: 23.904679 | N16: Grand Total | O16: 14384 | Q16: South Africa | R16: 18780.38 | T16: Dec | U16: 96685
Q17: United Arab Emirates | R17: 16672.08
Q18: Spain | R18: 12307
Q19: Grand Total | R19: 714519.93

Sheet V5
B1: YOUTUBE CHANNEL ANALYTICS | OVERVIEW DASHBOARD | AA1: KPI Store
AA2: =GETPIVOTDATA("Total Subscribers",'V4'!$A$3) -> 14384 | AB2: =TEXT(AA2,"#,##0") -> 14,384
AA3: =GETPIVOTDATA("Total Views",'V4'!$A$3) -> 1630679 | AB3: =TEXT(AA3,"#,##0") -> 1,630,679
AA4: =GETPIVOTDATA("Total Watch Time Hours",'V4'!$A$3) -> 136815 | AB4: =TEXT(AA4,"#,##0") -> 136,815
AA5: =GETPIVOTDATA("Estimated Revenue",'V4'!$A$3) -> 714519.93 | AB5: =TEXT(AA5,"$#,##0") -> $714,520
AA6: =GETPIVOTDATA("Avg View Duration",'V4'!$A$3) -> 23.904679 | AB6: =TEXT(AA6,"0.0") -> 23.9
